<mujoco model="BD-5">

  <compiler angle="radian" autolimits="true"/>
  <option iterations="1" ls_iterations="5" timestep="0.002" integrator="Euler" gravity="0 0 -9.81">
    <flag eulerdamp="disable"/>
  </option>

  <default>
    <joint limited="true" damping="1.084" armature="0.045" frictionloss="0.03" />
    <position inheritrange="1.0" kp="21.1" forcerange="-4.1 4.1"/>
    <default class="visualgeom">
      <geom material="visualgeom" contype="0" conaffinity="0" group="2"/>
    </default>
    <default class="collision">
      <geom group="3"/>
    </default>
  </default>

  <asset>
    <mesh name="BODY" file="assets/BODY.STL" maxhullvert="20"/>
    <mesh name="HIP_LEFT" file="assets/HIP_LEFT.STL" maxhullvert="20"/>
    <mesh name="HIP_ROLL_LEFT" file="assets/HIP_ROLL_LEFT.STL" maxhullvert="20"/>
    <mesh name="THIGH_LEFT" file="assets/THIGH_LEFT.STL" maxhullvert="20"/>
    <mesh name="CALF_LEFT" file="assets/CALF_LEFT.STL" maxhullvert="20"/>
    <mesh name="FOOT_LEFT" file="assets/FOOT_LEFT.STL" maxhullvert="20"/>
    <mesh name="HIP_RIGHT" file="assets/HIP_RIGHT.STL" maxhullvert="20"/>
    <mesh name="HIP_ROLL_RIGHT" file="assets/HIP_ROLL_RIGHT.STL" maxhullvert="20"/>
    <mesh name="THIGH_RIGHT" file="assets/THIGH_RIGHT.STL" maxhullvert="20"/>
    <mesh name="CALF_RIGHT" file="assets/CALF_RIGHT.STL" maxhullvert="20"/>
    <mesh name="FOOT_RIGHT" file="assets/FOOT_RIGHT.STL" maxhullvert="20"/>
    <material name="visualgeom" rgba="0.5 0.9 0.2 1" />
  </asset>

  <worldbody>
    <body name="base_body" pos="0 0 0.3170777382037414" quat="1 0 0 0">
      <freejoint name="base_body" />
      <site name="imu" size="0.01" pos="-0.00121 0.00083 0.05123" />
      <camera name="front" mode="trackcom" pos="0 -3.0 0.8170777382037414" xyaxes="1 0 0 0 0 1" />
      <camera name="track" mode="trackcom" pos="0 -3.0 0.8170777382037414" xyaxes="1 0 0 0 0 1" />
      <geom type="mesh" rgba="0.9098 0.44314 0.031373 1" mesh="BODY" class="visualgeom" />
      <inertial pos="-0.00035 0.00081 0.03798" quat="0.99982257 -0.0029832  -0.00544473 -0.01778418" mass="0.92059" diaginertia="0.00468827 0.00577802 0.00266137"/> 
      <body name="HIP_LEFT" pos="0 0.01425 -0.0436">
        <!-- original value was 0.05284-->
        <inertial pos="0.00185 0.0530 0.02786" quat="-0.57917026  0.19097798 -0.22686576  0.75935574" mass="0.101" diaginertia="2.89284572e-05 4.08891997e-05 4.55664031e-05" />
        <joint name="left_hip_yaw" pos="0 0 0" axis="0 0 1" range="-0.37899 0.37899" actuatorfrcrange="-4.1 4.1" damping="1.084" armature="0.045" frictionloss="0.03" />
        <geom type="mesh" rgba="0.25098 0.25098 0.25098 1" mesh="HIP_LEFT" class="visualgeom" />
        <body name="HIP_ROLL_LEFT" pos="0 0.05925 0.01275">
          <inertial pos="0 0 -0.02515" quat="3.0517578e-05 0.0000000e+00 0.0000000e+00 1.0000000e+00" mass="0.018" diaginertia="5.92983e-06 6.25751e-06 7.87081e-06" />
          <joint name="left_hip_roll" pos="0 0 0" axis="-1 0 0" range="-1.8827 0.38819" actuatorfrcrange="-4.1 4.1" damping="1.084" armature="0.045" frictionloss="0.03" />
          <geom type="mesh" rgba="0.25098 0.25098 0.25098 1" mesh="HIP_ROLL_LEFT" class="visualgeom" />
          <body name="THIGH_LEFT" pos="0 0 -0.05">
            <inertial pos="0 0.00215 -0.03525" quat=" 0.00351885 -0.00351885  0.70709803  0.70709803" mass="0.174" diaginertia="1.11453760e-04 5.11876103e-05 9.33676700e-05" />
            <joint name="left_hip_pitch" pos="0 0 0" axis="0 1 0" range="-1.7492 1.7492" actuatorfrcrange="-4.1 4.1" damping="1.084" armature="0.045" frictionloss="0.03" />
            <geom type="mesh" rgba="0.25098 0.25098 0.25098 1" mesh="THIGH_LEFT" class="visualgeom" />
            <body name="CALF_LEFT" pos="0 0 -0.0705">
              <inertial pos="0.00034 0.00191 -0.05036" quat="-0.06853654 -0.03586169  0.33373899  0.93948654" mass="0.098" diaginertia="4.49977826e-05 2.77625290e-05 3.42465984e-05" />
              <joint name="left_knee" pos="0 0 0" axis="0 -1 0" range="0 2.3829" actuatorfrcrange="-4.1 4.1" damping="1.084" armature="0.045" frictionloss="0.03" />
              <geom type="mesh" rgba="0.25098 0.25098 0.25098 1" mesh="CALF_LEFT" class="visualgeom" />
              <body name="FOOT_LEFT" pos="0 0 -0.07064">
                <inertial pos="0 0 -0.03334" quat="1. 0. 0. 0." mass="0.032" diaginertia="6.903700e-06 3.164244e-05 3.174429e-05" />
                <joint name="left_ankle" pos="0 0 0" axis="0 1 0" range="-1.8873 1.8873" actuatorfrcrange="-4.1 4.1" damping="1.084" armature="0.045" frictionloss="0.03" />
                <geom name="collision_foot_left" type="cylinder" size="0.013 0.065" pos="0 0 -0.0355" axisangle="0 1 0 -1.5708" class="collision"/>
                <geom type="mesh" rgba="0.9098 0.44314 0.031373 1" mesh="FOOT_LEFT" class="visualgeom" />
                <site group="0" name="left_foot_site" pos="0 0 -0.048"/>
              </body>
            </body>
          </body>
        </body>
      </body>
      <body name="HIP_RIGHT" pos="0 -0.01425 -0.0436">
        <inertial pos="0.00185 -0.0535 0.02786" quat="0.36885898 -0.33865446  0.64919201  0.5725434" mass="0.101" diaginertia="4.61603461e-05 4.12116205e-05 2.96353334e-05" />
        <joint name="right_hip_yaw" pos="0 0 0" axis="0 0 1" range="-0.37899 0.37899" actuatorfrcrange="-4.1 4.1" damping="1.084" armature="0.045" frictionloss="0.03" />
        <geom type="mesh" rgba="0.25098 0.25098 0.25098 1" mesh="HIP_RIGHT" class="visualgeom" />
        <body name="HIP_ROLL_RIGHT" pos="0 -0.05925 0.01275">
          <inertial pos="0 0 -0.02515" quat="3.0517578e-05 0.0000000e+00 0.0000000e+00 1.0000000e+00" mass="0.018" diaginertia="5.92983e-06 6.25751e-06 7.87081e-06" />
          <joint name="right_hip_roll" pos="0 0 0" axis="1 0 0" range="-1.8827 0.38819" actuatorfrcrange="-4.1 4.1" damping="1.084" armature="0.045" frictionloss="0.03" />
          <geom type="mesh" rgba="0.25098 0.25098 0.25098 1" mesh="HIP_ROLL_RIGHT" class="visualgeom" />
          <body name="THIGH_RIGHT" pos="0 0 -0.05">
            <inertial pos="0 0.00215 -0.03525" quat="0.00351885 -0.00351885  0.70709803  0.70709803" mass="0.174" diaginertia="1.11453760e-04 5.11876103e-05 9.33676700e-05" />
            <joint name="right_hip_pitch" pos="0 0 0" axis="0 1 0" range="-1.7492 1.7492" actuatorfrcrange="-4.1 4.1" damping="1.084" armature="0.045" frictionloss="0.03" />
            <geom type="mesh" rgba="0.25098 0.25098 0.25098 1" mesh="THIGH_RIGHT" class="visualgeom" />
            <body name="CALF_RIGHT" pos="0 0 -0.0705">
              <inertial pos="0.00034 0.00191 -0.05036" quat="-0.06853654 -0.03586169  0.33373899  0.93948654" mass="0.098" diaginertia="4.49977826e-05 2.77625290e-05 3.42465984e-05" />
              <joint name="right_knee" pos="0 0 0" axis="0 -1 0" range="0 2.3829" actuatorfrcrange="-4.1 4.1" damping="1.084" armature="0.045" frictionloss="0.03" />
              <geom type="mesh" rgba="0.25098 0.25098 0.25098 1" mesh="CALF_RIGHT" class="visualgeom" />
              <body name="FOOT_RIGHT" pos="0 0 -0.07064">
                <inertial pos="0 0 -0.03334" quat="1. 0. 0. 0." mass="0.032" diaginertia="6.903700e-06 3.164244e-05 3.174429e-05" />
                <joint name="right_ankle" pos="0 0 0" axis="0 1 0" range="-1.8873 1.8873" actuatorfrcrange="-4.1 4.1" damping="1.084" armature="0.045" frictionloss="0.03" />
                <geom name="collision_foot_right" type="cylinder" size="0.013 0.065" pos="0 0 -0.0355" axisangle="0 1 0 -1.5708" class="collision"/>
                <geom type="mesh" rgba="0.9098 0.44314 0.031373 1" mesh="FOOT_RIGHT" class="visualgeom" />
                <site group="0" name="right_foot_site" pos="0 0 -0.048"/>
              </body>
            </body>
          </body>
        </body>
      </body>
    </body>
  </worldbody>

  <actuator>
    <position name="left_hip_yaw" joint="left_hip_yaw" inheritrange="1"/>
    <position name="left_hip_roll" joint="left_hip_roll" inheritrange="1"/>
    <position name="left_hip_pitch" joint="left_hip_pitch" inheritrange="1"/>
    <position name="left_knee" joint="left_knee" inheritrange="1"/>
    <position name="left_ankle" joint="left_ankle" inheritrange="1"/>
    <position name="right_hip_yaw" joint="right_hip_yaw" inheritrange="1"/>
    <position name="right_hip_roll" joint="right_hip_roll" inheritrange="1"/>
    <position name="right_hip_pitch" joint="right_hip_pitch" inheritrange="1"/>
    <position name="right_knee" joint="right_knee" inheritrange="1"/>
    <position name="right_ankle" joint="right_ankle" inheritrange="1"/>
  </actuator>

  <sensor>
    <gyro site="imu" name="gyro"/>
    <velocimeter site="imu" name="local_linvel"/>
    <accelerometer site="imu" name="accelerometer"/>
    <framepos objtype="site" objname="imu" name="position"/>
    <framezaxis objtype="site" objname="imu" name="upvector"/>
    <framexaxis objtype="site" objname="imu" name="forwardvector"/>
    <framelinvel objtype="site" objname="imu" name="global_linvel"/>
    <frameangvel objtype="site" objname="imu" name="global_angvel"/>
    <framequat objtype="site" objname="imu" name="orientation"/>

    <framelinvel objtype="site" objname="left_foot_site" name="left_foot_global_linvel"/>
    <framelinvel objtype="site" objname="right_foot_site" name="right_foot_global_linvel"/>

    <framepos objtype="site" objname="left_foot_site" name="left_foot_pos"/>
    <framepos objtype="site" objname="right_foot_site" name="right_foot_pos"/>
  </sensor>
</mujoco>